# 实现 Promise.all 、Promise.race、Promise.finally

## 实现

`Promise.all` 可以将多个 `Promise` 实例包装成一个新的 `Promise` 实例。同时，成功和失败的返回值是不同的，成功的时候返回的是一个结果数组，而失败的时候则返回最先被 `reject` 失败状态的值。

```js
Promise.all = (promiseArray) => {
    const result = []
    const promiseCount = 0
    return new Promise((resolve, reject) => {
        // 统一处理
        // promiseCount 来进行处理，不能通过result.length来处理。
        const process = (value, index) => {
            result[index] = value
            if (++promiseCount === promiseArray.length) {
                resolve(result)
            }
        }
        for (let index = 0; index < promiseArray.length; index++) {
            const p = promiseArray[i]
            if (p && typeof p.then === 'function') {
                p.then((value) => {
                    process(value, index)
                }, reject)
            } else {
                process(p, index)
            }
        }
    })
}
```

注意：

1. 在获取 `promise` 的结果的时候，不要这样:
因为promise里面执行的代码可能是是异步的，直接`push`肯能会导致`result`和`promiseArray`返回的结果顺序不一致。

```js
result.push(value)
```

2. 也不能使用`promiseArray.length`与`result.length`长度进行判断,先看个示例：

```js
let  arr  = []
arr[2] = 1
console.log(arr.length)
// 3
```

直接对数组的索引赋值，也会数组的长足发生变化。

### Promise.all() 失败的情况也要正确返回实现

通常处理多个请求的时候我们会用`Promise.all()`方法。该方法指当所有在可迭代参数中的 `promises` 已完成，或者第一个传递的 `promise`（指 `reject`）失败时，返回 `promise`。但是当其中任何一个被拒绝的话。主`Promise.all([..])`就会立即被拒绝，并丢弃来自其他所有`promis`的全部结果。

`Promise.all()`方法只适合所有异步操作都成功的情况，如果有一个操作失败，就无法满足要求。

解决方式两种

* [Promise-allSettled](https://es6.ruanyifeng.com/#docs/promise#Promise-allSettled)
* [增加catch](https://es6.ruanyifeng.com/#docs/promise#Promise-allSettled)

### Promise-allSettled

### 增加catch

```js
var p1 = Promise.resolve(3);
var p2 = Promise.reject(2);
var p3 = new Promise((resolve, reject) => {
    setTimeout(resolve, 100, "foo");
}); 

Promise.all([p1, p2, p3]).then(values => { 
    console.log(values); // 永远走不到这里
}).catch(function(err) {
    console.log(err); // 2
});
```

这不是我们想要的。所以在使用这个方法的时候要记住为每个`promise`关联一个错误的处理函数.

```js
var p1 = Promise.resolve(3).catch(function(err) {
    return err;
});
var p2 = Promise.reject(2).catch(function(err) {
    return err;
});
var p3 = new Promise((resolve, reject) => {
    setTimeout(resolve, 100, "foo");
}).catch(function(err) {
    return err;
}); 

Promise.all([p1, p2, p3]).then(values => { 
    console.log(values); // [3, 2, "foo"]
}).catch(function(err) {
    console.log(1); //不会走到这里
});
```

## Promise.race

## Promise.prototype.finally()

[Promise.prototype.finally()](https://developer.mozilla.org/zh-CN/docs/Web/JavaScript/Reference/Global_Objects/Promise/finally)
方法返回一个`Promise`。在`promise`结束时，无论结果是`fulfilled`或者是`rejected`，都会执行指定的回调函数。这为在`Promise`是否成功完成后都需要执行的代码提供了一种方式。
**这避免了同样的语句需要在`then()`和`catch()`中各写一次的情况。**

```js
Promise.reject('1').finally(() => {
    return new Promise((resolve) => {
        setTimeout(() => {
            resolve('2')
        }, 2000)
    })
}).then(data => {
    console.log('data', data);
}, (err) => {
    console.log('err', err);  // 这里会输出 err 1
})


Promise.resolve('1').finally(() => {
    return new Promise((resolve,reject) => {
        setTimeout(() => {
            reject('2')
        }, 2000)
    })
}).then(data => {
    console.log('data', data); 
}, (err) => {
    console.log('err', err);  // err 2
})
```

```js
Promise.prototype.finally = (callback) => {
    // 执行完成后，返回一个promise，then函数返回一个 promise
    return this.then(data => {
        // callback 的返回值可能还是一个 promise， 需要等 promise 执行完成
        // 如果 callback 返回一个成功状态的的promise，则不会传递成功状态的promise的值，还是继续上一次promise的值继续向下传递。 
        Promise.resolve(callback()).then(() => data)
    }, err => {
        // callback 的返回值可能还是一个 promise， 需要等 promise 执行完成
        // 如果 callback 返回一个失败状态的的 promise，则传递失败状态的 promise 的值。
        Promise.resolve(callback()).then(() => { throw err })
    })
}
```
